Workbook

Sheet Dashboard
A1: REKAP STOK GUDANG SPPG
A3: PERIODE LAPORAN | L3: SEARCH BARANG
A4: Tanggal Mulai | B4: Tanggal Akhir | L4: Ketik kode / nama:
A5: 01/01/2026 | B5: 31/12/2026
L6: Kode | M6: Nama Barang | N6: Stok | O6: Status
L7: =IF(M4="","",FILTER('Master Barang'!A2:A500,(ISNUMBER(SEARCH(M4,'Master Barang'!A2:A500&""))+ISNUMBER(SEARCH(M4,'Master Barang'!B2:B500&"")))>0,"Tidak ditemukan"))
A8: Kode | B8: Nama Barang | C8: Stok Akhir | D8: Stok Minimum | E8: Kekurangan | F8: Status
A9: =IFERROR('Master Barang'!A2,"") -> PRL-001 | B9: =IF(A9="","",'Master Barang'!B2) -> natura desinfectant food grade 5l | C9: =IF(A9="","",'Master Barang'!E2+SUMIF('Barang Masuk'!$C:$C,A9,'Barang Masuk'!$E:$E)-SUMIF('Barang Keluar'!$C:$C,A9,'Barang Keluar'!$E:$E)) -> 2 | D9: =IF(A9="","",'Master Barang'!F2) -> 5 | E9: =IF(A9="","",MAX(0,D9-C9)) -> 3 | F9: =IF(A9="","",IF(C9<=0,"HABIS - BUAT PO",IF(C9<=D9,"TIPIS - BUAT PO","AMAN"))) -> TIPIS - BUAT PO
A10: =IFERROR('Master Barang'!A3,"") -> PRL-002 | B10: =IF(A10="","",'Master Barang'!B3) -> sunlight cairan pencuci piring 5l | C10: =IF(A10="","",'Master Barang'!E3+SUMIF('Barang Masuk'!$C:$C,A10,'Barang Masuk'!$E:$E)-SUMIF('Barang Keluar'!$C:$C,A10,'Barang Keluar'!$E:$E)) -> 4 | D10: =IF(A10="","",'Master Barang'!F3) -> 5 | E10: =IF(A10="","",MAX(0,D10-C10)) -> 1 | F10: =IF(A10="","",IF(C10<=0,"HABIS - BUAT PO",IF(C10<=D10,"TIPIS - BUAT PO","AMAN"))) -> TIPIS - BUAT PO
A11: =IFERROR('Master Barang'!A4,"") -> PRL-003 | B11: =IF(A11="","",'Master Barang'!B4) -> oixs cleaner 1l | C11: =IF(A11="","",'Master Barang'!E4+SUMIF('Barang Masuk'!$C:$C,A11,'Barang Masuk'!$E:$E)-SUMIF('Barang Keluar'!$C:$C,A11,'Barang Keluar'!$E:$E)) -> 1 | D11: =IF(A11="","",'Master Barang'!F4) -> 5 | E11: =IF(A11="","",MAX(0,D11-C11)) -> 4 | F11: =IF(A11="","",IF(C11<=0,"HABIS - BUAT PO",IF(C11<=D11,"TIPIS - BUAT PO","AMAN"))) -> TIPIS - BUAT PO
A12: =IFERROR('Master Barang'!A5,"") -> PRL-004 | B12: =IF(A12="","",'Master Barang'!B5) -> be clean tissue serbaguna | C12: =IF(A12="","",'Master Barang'!E5+SUMIF('Barang Masuk'!$C:$C,A12,'Barang Masuk'!$E:$E)-SUMIF('Barang Keluar'!$C:$C,A12,'Barang Keluar'!$E:$E)) -> 3 | D12: =IF(A12="","",'Master Barang'!F5) -> 5 | E12: =IF(A12="","",MAX(0,D12-C12)) -> 2 | F12: =IF(A12="","",IF(C12<=0,"HABIS - BUAT PO",IF(C12<=D12,"TIPIS - BUAT PO","AMAN"))) -> TIPIS - BUAT PO
A13: =IFERROR('Master Barang'!A6,"") -> PRL-005 | B13: =IF(A13="","",'Master Barang'!B6) -> spons cuci hijau | C13: =IF(A13="","",'Master Barang'!E6+SUMIF('Barang Masuk'!$C:$C,A13,'Barang Masuk'!$E:$E)-SUMIF('Barang Keluar'!$C:$C,A13,'Barang Keluar'!$E:$E)) -> 37 | D13: =IF(A13="","",'Master Barang'!F6) -> 10 | E13: =IF(A13="","",MAX(0,D13-C13)) -> 0 | F13: =IF(A13="","",IF(C13<=0,"HABIS - BUAT PO",IF(C13<=D13,"TIPIS - BUAT PO","AMAN"))) -> AMAN
A14: =IFERROR('Master Barang'!A7,"") -> PRL-006 | B14: =IF(A14="","",'Master Barang'!B7) -> sabut cuci stainless | C14: =IF(A14="","",'Master Barang'!E7+SUMIF('Barang Masuk'!$C:$C,A14,'Barang Masuk'!$E:$E)-SUMIF('Barang Keluar'!$C:$C,A14,'Barang Keluar'!$E:$E)) -> 22 | D14: =IF(A14="","",'Master Barang'!F7) -> 5 | E14: =IF(A14="","",MAX(0,D14-C14)) -> 0 | F14: =IF(A14="","",IF(C14<=0,"HABIS - BUAT PO",IF(C14<=D14,"TIPIS - BUAT PO","AMAN"))) -> AMAN
A15: =IFERROR('Master Barang'!A8,"") -> PRL-007 | B15: =IF(A15="","",'Master Barang'!B8) -> plastik kresek besar merah 50pc | C15: =IF(A15="","",'Master Barang'!E8+SUMIF('Barang Masuk'!$C:$C,A15,'Barang Masuk'!$E:$E)-SUMIF('Barang Keluar'!$C:$C,A15,'Barang Keluar'!$E:$E)) -> 8 | D15: =IF(A15="","",'Master Barang'!F8) -> 5 | E15: =IF(A15="","",MAX(0,D15-C15)) -> 0 | F15: =IF(A15="","",IF(C15<=0,"HABIS - BUAT PO",IF(C15<=D15,"TIPIS - BUAT PO","AMAN"))) -> AMAN
A16: =IFERROR('Master Barang'!A9,"") -> PRL-008 | B16: =IF(A16="","",'Master Barang'!B9) -> lap besar | C16: =IF(A16="","",'Master Barang'!E9+SUMIF('Barang Masuk'!$C:$C,A16,'Barang Masuk'!$E:$E)-SUMIF('Barang Keluar'!$C:$C,A16,'Barang Keluar'!$E:$E)) -> 4 | D16: =IF(A16="","",'Master Barang'!F9) -> 5 | E16: =IF(A16="","",MAX(0,D16-C16)) -> 1 | F16: =IF(A16="","",IF(C16<=0,"HABIS - BUAT PO",IF(C16<=D16,"TIPIS - BUAT PO","AMAN"))) -> TIPIS - BUAT PO
A17: =IFERROR('Master Barang'!A10,"") -> PRL-009 | B17: =IF(A17="","",'Master Barang'!B10) -> lap microfiber | C17: =IF(A17="","",'Master Barang'!E10+SUMIF('Barang Masuk'!$C:$C,A17,'Barang Masuk'!$E:$E)-SUMIF('Barang Keluar'!$C:$C,A17,'Barang Keluar'!$E:$E)) -> 67 | D17: =IF(A17="","",'Master Barang'!F10) -> 5 | E17: =IF(A17="","",MAX(0,D17-C17)) -> 0 | F17: =IF(A17="","",IF(C17<=0,"HABIS - BUAT PO",IF(C17<=D17,"TIPIS - BUAT PO","AMAN"))) -> AMAN
A18: =IFERROR('Master Barang'!A11,"") -> PRL-010 | B18: =IF(A18="","",'Master Barang'!B11) -> lap kecil | C18: =IF(A18="","",'Master Barang'!E11+SUMIF('Barang Masuk'!$C:$C,A18,'Barang Masuk'!$E:$E)-SUMIF('Barang Keluar'!$C:$C,A18,'Barang Keluar'!$E:$E)) -> 7 | D18: =IF(A18="","",'Master Barang'!F11) -> 5 | E18: =IF(A18="","",MAX(0,D18-C18)) -> 0 | F18: =IF(A18="","",IF(C18<=0,"HABIS - BUAT PO",IF(C18<=D18,"TIPIS - BUAT PO","AMAN"))) -> AMAN
A19: =IFERROR('Master Barang'!A12,"") -> PRL-011 | B19: =IF(A19="","",'Master Barang'!B12) -> kanebo kecil | C19: =IF(A19="","",'Master Barang'!E12+SUMIF('Barang Masuk'!$C:$C,A19,'Barang Masuk'!$E:$E)-SUMIF('Barang Keluar'!$C:$C,A19,'Barang Keluar'!$E:$E)) -> 6 | D19: =IF(A19="","",'Master Barang'!F12) -> 5 | E19: =IF(A19="","",MAX(0,D19-C19)) -> 0 | F19: =IF(A19="","",IF(C19<=0,"HABIS - BUAT PO",IF(C19<=D19,"TIPIS - BUAT PO","AMAN"))) -> AMAN
A20: =IFERROR('Master Barang'!A13,"") -> PRL-012 | B20: =IF(A20="","",'Master Barang'!B13) -> plastik 1/4kg joyoboyo 100 lembar | C20: =IF(A20="","",'Master Barang'!E13+SUMIF('Barang Masuk'!$C:$C,A20,'Barang Masuk'!$E:$E)-SUMIF('Barang Keluar'!$C:$C,A20,'Barang Keluar'!$E:$E)) -> 28 | D20: =IF(A20="","",'Master Barang'!F13) -> 5 | E20: =IF(A20="","",MAX(0,D20-C20)) -> 0 | F20: =IF(A20="","",IF(C20<=0,"HABIS - BUAT PO",IF(C20<=D20,"TIPIS - BUAT PO","AMAN"))) -> AMAN
... A108: =IFERROR('Master Barang'!A101,"") -> 0 | B108: =IF(A108="","",'Master Barang'!B101) -> 0 | C108: =IF(A108="","",'Master Barang'!E101+SUMIF('Barang Masuk'!$C:$C,A108,'Barang Masuk'!$E:$E)-SUMIF('Barang Keluar'!$C:$C,A108,'Barang Keluar'!$E:$E)) -> 0 | D108: =IF(A108="","",'Master Barang'!F101) -> 0 | E108: =IF(A108="","",MAX(0,D108-C108)) -> 0 | F108: =IF(A108="","",IF(C108<=0,"HABIS - BUAT PO",IF(C108<=D108,"TIPIS - BUAT PO","AMAN"))) -> HABIS - BUAT PO
A111: KPI | B111: Nilai
A112: Total Jenis Barang | B112: =COUNTA('Master Barang'!A2:A500) -> 33
A113: Total Stok Awal | B113: =SUM('Master Barang'!E2:E500) -> 2366
A114: Total Barang Masuk | B114: =SUM('Barang Masuk'!E2:E1001) -> 0
A115: Total Barang Keluar | B115: =SUM('Barang Keluar'!E2:E1001) -> 0
A116: Barang Tipis/Habis | B116: =COUNTIF(F9:F108,"<>AMAN")-COUNTIF(F9:F108,"") -> 83

Sheet Barang Masuk
A1: Tanggal | B1: No. Dokumen | C1: Kode Barang | D1: Nama Barang | E1: Qty Masuk | F1: Satuan | G1: Supplier/Sumber | H1: Keterangan
C2: PRL-002 | D2: =IFERROR(XLOOKUP(C2,'Master Barang'!$A:$A,'Master Barang'!$B:$B,""),"") | F2: =IFERROR(XLOOKUP(C2,'Master Barang'!$A:$A,'Master Barang'!$D:$D,""),"")
D3: =IFERROR(XLOOKUP(C3,'Master Barang'!$A:$A,'Master Barang'!$B:$B,""),"") | F3: =IFERROR(XLOOKUP(C3,'Master Barang'!$A:$A,'Master Barang'!$D:$D,""),"")
D4: =IFERROR(XLOOKUP(C4,'Master Barang'!$A:$A,'Master Barang'!$B:$B,""),"") | F4: =IFERROR(XLOOKUP(C4,'Master Barang'!$A:$A,'Master Barang'!$D:$D,""),"")
D5: =IFERROR(XLOOKUP(C5,'Master Barang'!$A:$A,'Master Barang'!$B:$B,""),"") | F5: =IFERROR(XLOOKUP(C5,'Master Barang'!$A:$A,'Master Barang'!$D:$D,""),"")
D6: =IFERROR(XLOOKUP(C6,'Master Barang'!$A:$A,'Master Barang'!$B:$B,""),"") | F6: =IFERROR(XLOOKUP(C6,'Master Barang'!$A:$A,'Master Barang'!$D:$D,""),"")
D7: =IFERROR(XLOOKUP(C7,'Master Barang'!$A:$A,'Master Barang'!$B:$B,""),"") | F7: =IFERROR(XLOOKUP(C7,'Master Barang'!$A:$A,'Master Barang'!$D:$D,""),"")
D8: =IFERROR(XLOOKUP(C8,'Master Barang'!$A:$A,'Master Barang'!$B:$B,""),"") | F8: =IFERROR(XLOOKUP(C8,'Master Barang'!$A:$A,'Master Barang'!$D:$D,""),"")
D9: =IFERROR(XLOOKUP(C9,'Master Barang'!$A:$A,'Master Barang'!$B:$B,""),"") | F9: =IFERROR(XLOOKUP(C9,'Master Barang'!$A:$A,'Master Barang'!$D:$D,""),"")
D10: =IFERROR(XLOOKUP(C10,'Master Barang'!$A:$A,'Master Barang'!$B:$B,""),"") | F10: =IFERROR(XLOOKUP(C10,'Master Barang'!$A:$A,'Master Barang'!$D:$D,""),"")
D11: =IFERROR(XLOOKUP(C11,'Master Barang'!$A:$A,'Master Barang'!$B:$B,""),"") | F11: =IFERROR(XLOOKUP(C11,'Master Barang'!$A:$A,'Master Barang'!$D:$D,""),"")
D12: =IFERROR(XLOOKUP(C12,'Master Barang'!$A:$A,'Master Barang'!$B:$B,""),"") | F12: =IFERROR(XLOOKUP(C12,'Master Barang'!$A:$A,'Master Barang'!$D:$D,""),"")
D13: =IFERROR(XLOOKUP(C13,'Master Barang'!$A:$A,'Master Barang'!$B:$B,""),"") | F13: =IFERROR(XLOOKUP(C13,'Master Barang'!$A:$A,'Master Barang'!$D:$D,""),"")
D14: =IFERROR(XLOOKUP(C14,'Master Barang'!$A:$A,'Master Barang'!$B:$B,""),"") | F14: =IFERROR(XLOOKUP(C14,'Master Barang'!$A:$A,'Master Barang'!$D:$D,""),"")
... D1001: =IFERROR(XLOOKUP(C1001,'Master Barang'!$A:$A,'Master Barang'!$B:$B,""),"") | F1001: =IFERROR(XLOOKUP(C1001,'Master Barang'!$A:$A,'Master Barang'!$D:$D,""),"")

Sheet Barang Keluar
A1: Tanggal | B1: No. Dokumen | C1: Kode Barang | D1: Nama Barang | E1: Qty Keluar | F1: Satuan | G1: Tujuan/Pengambil | H1: Keterangan
D2: =IFERROR(XLOOKUP(C2,'Master Barang'!$A:$A,'Master Barang'!$B:$B,""),"") | F2: =IFERROR(XLOOKUP(C2,'Master Barang'!$A:$A,'Master Barang'!$D:$D,""),"")
D3: =IFERROR(XLOOKUP(C3,'Master Barang'!$A:$A,'Master Barang'!$B:$B,""),"") | F3: =IFERROR(XLOOKUP(C3,'Master Barang'!$A:$A,'Master Barang'!$D:$D,""),"")
D4: =IFERROR(XLOOKUP(C4,'Master Barang'!$A:$A,'Master Barang'!$B:$B,""),"") | F4: =IFERROR(XLOOKUP(C4,'Master Barang'!$A:$A,'Master Barang'!$D:$D,""),"")
D5: =IFERROR(XLOOKUP(C5,'Master Barang'!$A:$A,'Master Barang'!$B:$B,""),"") | F5: =IFERROR(XLOOKUP(C5,'Master Barang'!$A:$A,'Master Barang'!$D:$D,""),"")
D6: =IFERROR(XLOOKUP(C6,'Master Barang'!$A:$A,'Master Barang'!$B:$B,""),"") | F6: =IFERROR(XLOOKUP(C6,'Master Barang'!$A:$A,'Master Barang'!$D:$D,""),"")
D7: =IFERROR(XLOOKUP(C7,'Master Barang'!$A:$A,'Master Barang'!$B:$B,""),"") | F7: =IFERROR(XLOOKUP(C7,'Master Barang'!$A:$A,'Master Barang'!$D:$D,""),"")
D8: =IFERROR(XLOOKUP(C8,'Master Barang'!$A:$A,'Master Barang'!$B:$B,""),"") | F8: =IFERROR(XLOOKUP(C8,'Master Barang'!$A:$A,'Master Barang'!$D:$D,""),"")
D9: =IFERROR(XLOOKUP(C9,'Master Barang'!$A:$A,'Master Barang'!$B:$B,""),"") | F9: =IFERROR(XLOOKUP(C9,'Master Barang'!$A:$A,'Master Barang'!$D:$D,""),"")
D10: =IFERROR(XLOOKUP(C10,'Master Barang'!$A:$A,'Master Barang'!$B:$B,""),"") | F10: =IFERROR(XLOOKUP(C10,'Master Barang'!$A:$A,'Master Barang'!$D:$D,""),"")
D11: =IFERROR(XLOOKUP(C11,'Master Barang'!$A:$A,'Master Barang'!$B:$B,""),"") | F11: =IFERROR(XLOOKUP(C11,'Master Barang'!$A:$A,'Master Barang'!$D:$D,""),"")
D12: =IFERROR(XLOOKUP(C12,'Master Barang'!$A:$A,'Master Barang'!$B:$B,""),"") | F12: =IFERROR(XLOOKUP(C12,'Master Barang'!$A:$A,'Master Barang'!$D:$D,""),"")
D13: =IFERROR(XLOOKUP(C13,'Master Barang'!$A:$A,'Master Barang'!$B:$B,""),"") | F13: =IFERROR(XLOOKUP(C13,'Master Barang'!$A:$A,'Master Barang'!$D:$D,""),"")
... D1001: =IFERROR(XLOOKUP(C1001,'Master Barang'!$A:$A,'Master Barang'!$B:$B,""),"") | F1001: =IFERROR(XLOOKUP(C1001,'Master Barang'!$A:$A,'Master Barang'!$D:$D,""),"")

Sheet Laporan Pengeluaran
A1: LAPORAN PENGELUARAN
A3: Tanggal Mulai | B3: Tanggal Akhir | F3: REKAP HARIAN | I3: REKAP MINGGUAN | M3: PENGELUARAN HARIAN PER BARANG
A4: 01/01/2026 | B4: 31/12/2026
A6: Kode | B6: Nama Barang | C6: Satuan | D6: Qty Keluar Periode
A7: =IFERROR('Master Barang'!A2,"") -> PRL-001 | B7: =IFERROR('Master Barang'!B2,"") -> natura desinfectant food grade 5l | C7: =IFERROR('Master Barang'!D2,"") -> pcs | D7: =IF(A7="","",SUMIFS('Barang Keluar'!$E:$E,'Barang Keluar'!$C:$C,A7,'Barang Keluar'!$A:$A,">="&$A$4,'Barang Keluar'!$A:$A,"<="&$B$4)) -> 0 | F7: Tanggal | G7: Qty Keluar | I7: Awal Minggu | J7: Akhir Minggu | K7: Qty Keluar | M7: Tanggal | N7: Kode | O7: Nama Barang | P7: Qty
A8: =IFERROR('Master Barang'!A3,"") -> PRL-002 | B8: =IFERROR('Master Barang'!B3,"") -> sunlight cairan pencuci piring 5l | C8: =IFERROR('Master Barang'!D3,"") -> pcs | D8: =IF(A8="","",SUMIFS('Barang Keluar'!$E:$E,'Barang Keluar'!$C:$C,A8,'Barang Keluar'!$A:$A,">="&$A$4,'Barang Keluar'!$A:$A,"<="&$B$4)) -> 0 | F8: =IF($A$4+ROW()-8>$B$4,"",$A$4+ROW()-8) -> 46023 | G8: =IF(F8="","",SUMIFS('Barang Keluar'!$E:$E,'Barang Keluar'!$A:$A,F8)) -> 0 | I8: =IF($A$4+7*(ROW()-8)-WEEKDAY($A$4,2)+1>$B$4,"",$A$4+7*(ROW()-8)-WEEKDAY($A$4,2)+1) -> 46020 | J8: =IF(I8="","",I8+6) -> 46026 | K8: =IF(I8="","",SUMIFS('Barang Keluar'!$E:$E,'Barang Keluar'!$A:$A,">="&I8,'Barang Keluar'!$A:$A,"<="&J8)) -> 0 | M8: =IF($A$4+0>$B$4,"",$A$4+0) -> 46023 | N8: =IF(M8="","",'Master Barang'!A2) -> PRL-001 | O8: =IF(N8="","",'Master Barang'!B2) -> natura desinfectant food grade 5l | P8: =IF(OR(M8="",N8=""),"",SUMIFS('Barang Keluar'!$E:$E,'Barang Keluar'!$A:$A,M8,'Barang Keluar'!$C:$C,N8)) -> 0
A9: =IFERROR('Master Barang'!A4,"") -> PRL-003 | B9: =IFERROR('Master Barang'!B4,"") -> oixs cleaner 1l | C9: =IFERROR('Master Barang'!D4,"") -> pcs | D9: =IF(A9="","",SUMIFS('Barang Keluar'!$E:$E,'Barang Keluar'!$C:$C,A9,'Barang Keluar'!$A:$A,">="&$A$4,'Barang Keluar'!$A:$A,"<="&$B$4)) -> 0 | F9: =IF($A$4+ROW()-8>$B$4,"",$A$4+ROW()-8) -> 46024 | G9: =IF(F9="","",SUMIFS('Barang Keluar'!$E:$E,'Barang Keluar'!$A:$A,F9)) -> 0 | I9: =IF($A$4+7*(ROW()-8)-WEEKDAY($A$4,2)+1>$B$4,"",$A$4+7*(ROW()-8)-WEEKDAY($A$4,2)+1) -> 46027 | J9: =IF(I9="","",I9+6) -> 46033 | K9: =IF(I9="","",SUMIFS('Barang Keluar'!$E:$E,'Barang Keluar'!$A:$A,">="&I9,'Barang Keluar'!$A:$A,"<="&J9)) -> 0 | M9: =IF($A$4+0>$B$4,"",$A$4+0) -> 46023 | N9: =IF(M9="","",'Master Barang'!A3) -> PRL-002 | O9: =IF(N9="","",'Master Barang'!B3) -> sunlight cairan pencuci piring 5l | P9: =IF(OR(M9="",N9=""),"",SUMIFS('Barang Keluar'!$E:$E,'Barang Keluar'!$A:$A,M9,'Barang Keluar'!$C:$C,N9)) -> 0
A10: =IFERROR('Master Barang'!A5,"") -> PRL-004 | B10: =IFERROR('Master Barang'!B5,"") -> be clean tissue serbaguna | C10: =IFERROR('Master Barang'!D5,"") -> pcs | D10: =IF(A10="","",SUMIFS('Barang Keluar'!$E:$E,'Barang Keluar'!$C:$C,A10,'Barang Keluar'!$A:$A,">="&$A$4,'Barang Keluar'!$A:$A,"<="&$B$4)) -> 0 | F10: =IF($A$4+ROW()-8>$B$4,"",$A$4+ROW()-8) -> 46025 | G10: =IF(F10="","",SUMIFS('Barang Keluar'!$E:$E,'Barang Keluar'!$A:$A,F10)) -> 0 | I10: =IF($A$4+7*(ROW()-8)-WEEKDAY($A$4,2)+1>$B$4,"",$A$4+7*(ROW()-8)-WEEKDAY($A$4,2)+1) -> 46034 | J10: =IF(I10="","",I10+6) -> 46040 | K10: =IF(I10="","",SUMIFS('Barang Keluar'!$E:$E,'Barang Keluar'!$A:$A,">="&I10,'Barang Keluar'!$A:$A,"<="&J10)) -> 0 | M10: =IF($A$4+0>$B$4,"",$A$4+0) -> 46023 | N10: =IF(M10="","",'Master Barang'!A4) -> PRL-003 | O10: =IF(N10="","",'Master Barang'!B4) -> oixs cleaner 1l | P10: =IF(OR(M10="",N10=""),"",SUMIFS('Barang Keluar'!$E:$E,'Barang Keluar'!$A:$A,M10,'Barang Keluar'!$C:$C,N10)) -> 0
A11: =IFERROR('Master Barang'!A6,"") -> PRL-005 | B11: =IFERROR('Master Barang'!B6,"") -> spons cuci hijau | C11: =IFERROR('Master Barang'!D6,"") -> pcs | D11: =IF(A11="","",SUMIFS('Barang Keluar'!$E:$E,'Barang Keluar'!$C:$C,A11,'Barang Keluar'!$A:$A,">="&$A$4,'Barang Keluar'!$A:$A,"<="&$B$4)) -> 0 | F11: =IF($A$4+ROW()-8>$B$4,"",$A$4+ROW()-8) -> 46026 | G11: =IF(F11="","",SUMIFS('Barang Keluar'!$E:$E,'Barang Keluar'!$A:$A,F11)) -> 0 | I11: =IF($A$4+7*(ROW()-8)-WEEKDAY($A$4,2)+1>$B$4,"",$A$4+7*(ROW()-8)-WEEKDAY($A$4,2)+1) -> 46041 | J11: =IF(I11="","",I11+6) -> 46047 | K11: =IF(I11="","",SUMIFS('Barang Keluar'!$E:$E,'Barang Keluar'!$A:$A,">="&I11,'Barang Keluar'!$A:$A,"<="&J11)) -> 0 | M11: =IF($A$4+0>$B$4,"",$A$4+0) -> 46023 | N11: =IF(M11="","",'Master Barang'!A5) -> PRL-004 | O11: =IF(N11="","",'Master Barang'!B5) -> be clean tissue serbaguna | P11: =IF(OR(M11="",N11=""),"",SUMIFS('Barang Keluar'!$E:$E,'Barang Keluar'!$A:$A,M11,'Barang Keluar'!$C:$C,N11)) -> 0
A12: =IFERROR('Master Barang'!A7,"") -> PRL-006 | B12: =IFERROR('Master Barang'!B7,"") -> sabut cuci stainless | C12: =IFERROR('Master Barang'!D7,"") -> pcs | D12: =IF(A12="","",SUMIFS('Barang Keluar'!$E:$E,'Barang Keluar'!$C:$C,A12,'Barang Keluar'!$A:$A,">="&$A$4,'Barang Keluar'!$A:$A,"<="&$B$4)) -> 0 | F12: =IF($A$4+ROW()-8>$B$4,"",$A$4+ROW()-8) -> 46027 | G12: =IF(F12="","",SUMIFS('Barang Keluar'!$E:$E,'Barang Keluar'!$A:$A,F12)) -> 0 | I12: =IF($A$4+7*(ROW()-8)-WEEKDAY($A$4,2)+1>$B$4,"",$A$4+7*(ROW()-8)-WEEKDAY($A$4,2)+1) -> 46048 | J12: =IF(I12="","",I12+6) -> 46054 | K12: =IF(I12="","",SUMIFS('Barang Keluar'!$E:$E,'Barang Keluar'!$A:$A,">="&I12,'Barang Keluar'!$A:$A,"<="&J12)) -> 0 | M12: =IF($A$4+0>$B$4,"",$A$4+0) -> 46023 | N12: =IF(M12="","",'Master Barang'!A6) -> PRL-005 | O12: =IF(N12="","",'Master Barang'!B6) -> spons cuci hijau | P12: =IF(OR(M12="",N12=""),"",SUMIFS('Barang Keluar'!$E:$E,'Barang Keluar'!$A:$A,M12,'Barang Keluar'!$C:$C,N12)) -> 0
A13: =IFERROR('Master Barang'!A8,"") -> PRL-007 | B13: =IFERROR('Master Barang'!B8,"") -> plastik kresek besar merah 50pc | C13: =IFERROR('Master Barang'!D8,"") -> pack | D13: =IF(A13="","",SUMIFS('Barang Keluar'!$E:$E,'Barang Keluar'!$C:$C,A13,'Barang Keluar'!$A:$A,">="&$A$4,'Barang Keluar'!$A:$A,"<="&$B$4)) -> 0 | F13: =IF($A$4+ROW()-8>$B$4,"",$A$4+ROW()-8) -> 46028 | G13: =IF(F13="","",SUMIFS('Barang Keluar'!$E:$E,'Barang Keluar'!$A:$A,F13)) -> 0 | I13: =IF($A$4+7*(ROW()-8)-WEEKDAY($A$4,2)+1>$B$4,"",$A$4+7*(ROW()-8)-WEEKDAY($A$4,2)+1) -> 46055 | J13: =IF(I13="","",I13+6) -> 46061 | K13: =IF(I13="","",SUMIFS('Barang Keluar'!$E:$E,'Barang Keluar'!$A:$A,">="&I13,'Barang Keluar'!$A:$A,"<="&J13)) -> 0 | M13: =IF($A$4+0>$B$4,"",$A$4+0) -> 46023 | N13: =IF(M13="","",'Master Barang'!A7) -> PRL-006 | O13: =IF(N13="","",'Master Barang'!B7) -> sabut cuci stainless | P13: =IF(OR(M13="",N13=""),"",SUMIFS('Barang Keluar'!$E:$E,'Barang Keluar'!$A:$A,M13,'Barang Keluar'!$C:$C,N13)) -> 0
A14: =IFERROR('Master Barang'!A9,"") -> PRL-008 | B14: =IFERROR('Master Barang'!B9,"") -> lap besar | C14: =IFERROR('Master Barang'!D9,"") -> pcs | D14: =IF(A14="","",SUMIFS('Barang Keluar'!$E:$E,'Barang Keluar'!$C:$C,A14,'Barang Keluar'!$A:$A,">="&$A$4,'Barang Keluar'!$A:$A,"<="&$B$4)) -> 0 | F14: =IF($A$4+ROW()-8>$B$4,"",$A$4+ROW()-8) -> 46029 | G14: =IF(F14="","",SUMIFS('Barang Keluar'!$E:$E,'Barang Keluar'!$A:$A,F14)) -> 0 | I14: =IF($A$4+7*(ROW()-8)-WEEKDAY($A$4,2)+1>$B$4,"",$A$4+7*(ROW()-8)-WEEKDAY($A$4,2)+1) -> 46062 | J14: =IF(I14="","",I14+6) -> 46068 | K14: =IF(I14="","",SUMIFS('Barang Keluar'!$E:$E,'Barang Keluar'!$A:$A,">="&I14,'Barang Keluar'!$A:$A,"<="&J14)) -> 0 | M14: =IF($A$4+0>$B$4,"",$A$4+0) -> 46023 | N14: =IF(M14="","",'Master Barang'!A8) -> PRL-007 | O14: =IF(N14="","",'Master Barang'!B8) -> plastik kresek besar merah 50pc | P14: =IF(OR(M14="",N14=""),"",SUMIFS('Barang Keluar'!$E:$E,'Barang Keluar'!$A:$A,M14,'Barang Keluar'!$C:$C,N14)) -> 0
A15: =IFERROR('Master Barang'!A10,"") -> PRL-009 | B15: =IFERROR('Master Barang'!B10,"") -> lap microfiber | C15: =IFERROR('Master Barang'!D10,"") -> pcs | D15: =IF(A15="","",SUMIFS('Barang Keluar'!$E:$E,'Barang Keluar'!$C:$C,A15,'Barang Keluar'!$A:$A,">="&$A$4,'Barang Keluar'!$A:$A,"<="&$B$4)) -> 0 | F15: =IF($A$4+ROW()-8>$B$4,"",$A$4+ROW()-8) -> 46030 | G15: =IF(F15="","",SUMIFS('Barang Keluar'!$E:$E,'Barang Keluar'!$A:$A,F15)) -> 0 | I15: =IF($A$4+7*(ROW()-8)-WEEKDAY($A$4,2)+1>$B$4,"",$A$4+7*(ROW()-8)-WEEKDAY($A$4,2)+1) -> 46069 | J15: =IF(I15="","",I15+6) -> 46075 | K15: =IF(I15="","",SUMIFS('Barang Keluar'!$E:$E,'Barang Keluar'!$A:$A,">="&I15,'Barang Keluar'!$A:$A,"<="&J15)) -> 0 | M15: =IF($A$4+0>$B$4,"",$A$4+0) -> 46023 | N15: =IF(M15="","",'Master Barang'!A9) -> PRL-008 | O15: =IF(N15="","",'Master Barang'!B9) -> lap besar | P15: =IF(OR(M15="",N15=""),"",SUMIFS('Barang Keluar'!$E:$E,'Barang Keluar'!$A:$A,M15,'Barang Keluar'!$C:$C,N15)) -> 0
A16: =IFERROR('Master Barang'!A11,"") -> PRL-010 | B16: =IFERROR('Master Barang'!B11,"") -> lap kecil | C16: =IFERROR('Master Barang'!D11,"") -> pcs | D16: =IF(A16="","",SUMIFS('Barang Keluar'!$E:$E,'Barang Keluar'!$C:$C,A16,'Barang Keluar'!$A:$A,">="&$A$4,'Barang Keluar'!$A:$A,"<="&$B$4)) -> 0 | F16: =IF($A$4+ROW()-8>$B$4,"",$A$4+ROW()-8) -> 46031 | G16: =IF(F16="","",SUMIFS('Barang Keluar'!$E:$E,'Barang Keluar'!$A:$A,F16)) -> 0 | I16: =IF($A$4+7*(ROW()-8)-WEEKDAY($A$4,2)+1>$B$4,"",$A$4+7*(ROW()-8)-WEEKDAY($A$4,2)+1) -> 46076 | J16: =IF(I16="","",I16+6) -> 46082 | K16: =IF(I16="","",SUMIFS('Barang Keluar'!$E:$E,'Barang Keluar'!$A:$A,">="&I16,'Barang Keluar'!$A:$A,"<="&J16)) -> 0 | M16: =IF($A$4+0>$B$4,"",$A$4+0) -> 46023 | N16: =IF(M16="","",'Master Barang'!A10) -> PRL-009 | O16: =IF(N16="","",'Master Barang'!B10) -> lap microfiber | P16: =IF(OR(M16="",N16=""),"",SUMIFS('Barang Keluar'!$E:$E,'Barang Keluar'!$A:$A,M16,'Barang Keluar'!$C:$C,N16)) -> 0
A17: =IFERROR('Master Barang'!A12,"") -> PRL-011 | B17: =IFERROR('Master Barang'!B12,"") -> kanebo kecil | C17: =IFERROR('Master Barang'!D12,"") -> pcs | D17: =IF(A17="","",SUMIFS('Barang Keluar'!$E:$E,'Barang Keluar'!$C:$C,A17,'Barang Keluar'!$A:$A,">="&$A$4,'Barang Keluar'!$A:$A,"<="&$B$4)) -> 0 | F17: =IF($A$4+ROW()-8>$B$4,"",$A$4+ROW()-8) -> 46032 | G17: =IF(F17="","",SUMIFS('Barang Keluar'!$E:$E,'Barang Keluar'!$A:$A,F17)) -> 0 | I17: =IF($A$4+7*(ROW()-8)-WEEKDAY($A$4,2)+1>$B$4,"",$A$4+7*(ROW()-8)-WEEKDAY($A$4,2)+1) -> 46083 | J17: =IF(I17="","",I17+6) -> 46089 | K17: =IF(I17="","",SUMIFS('Barang Keluar'!$E:$E,'Barang Keluar'!$A:$A,">="&I17,'Barang Keluar'!$A:$A,"<="&J17)) -> 0 | M17: =IF($A$4+0>$B$4,"",$A$4+0) -> 46023 | N17: =IF(M17="","",'Master Barang'!A11) -> PRL-010 | O17: =IF(N17="","",'Master Barang'!B11) -> lap kecil | P17: =IF(OR(M17="",N17=""),"",SUMIFS('Barang Keluar'!$E:$E,'Barang Keluar'!$A:$A,M17,'Barang Keluar'!$C:$C,N17)) -> 0
A18: =IFERROR('Master Barang'!A13,"") -> PRL-012 | B18: =IFERROR('Master Barang'!B13,"") -> plastik 1/4kg joyoboyo 100 lembar | C18: =IFERROR('Master Barang'!D13,"") -> pack | D18: =IF(A18="","",SUMIFS('Barang Keluar'!$E:$E,'Barang Keluar'!$C:$C,A18,'Barang Keluar'!$A:$A,">="&$A$4,'Barang Keluar'!$A:$A,"<="&$B$4)) -> 0 | F18: =IF($A$4+ROW()-8>$B$4,"",$A$4+ROW()-8) -> 46033 | G18: =IF(F18="","",SUMIFS('Barang Keluar'!$E:$E,'Barang Keluar'!$A:$A,F18)) -> 0 | I18: =IF($A$4+7*(ROW()-8)-WEEKDAY($A$4,2)+1>$B$4,"",$A$4+7*(ROW()-8)-WEEKDAY($A$4,2)+1) -> 46090 | J18: =IF(I18="","",I18+6) -> 46096 | K18: =IF(I18="","",SUMIFS('Barang Keluar'!$E:$E,'Barang Keluar'!$A:$A,">="&I18,'Barang Keluar'!$A:$A,"<="&J18)) -> 0 | M18: =IF($A$4+0>$B$4,"",$A$4+0) -> 46023 | N18: =IF(M18="","",'Master Barang'!A12) -> PRL-011 | O18: =IF(N18="","",'Master Barang'!B12) -> kanebo kecil | P18: =IF(OR(M18="",N18=""),"",SUMIFS('Barang Keluar'!$E:$E,'Barang Keluar'!$A:$A,M18,'Barang Keluar'!$C:$C,N18)) -> 0
A19: =IFERROR('Master Barang'!A14,"") -> PRL-013 | B19: =IFERROR('Master Barang'!B14,"") -> sarung tangan plastik kaka 100 pcs | C19: =IFERROR('Master Barang'!D14,"") -> pack | D19: =IF(A19="","",SUMIFS('Barang Keluar'!$E:$E,'Barang Keluar'!$C:$C,A19,'Barang Keluar'!$A:$A,">="&$A$4,'Barang Keluar'!$A:$A,"<="&$B$4)) -> 0 | F19: =IF($A$4+ROW()-8>$B$4,"",$A$4+ROW()-8) -> 46034 | G19: =IF(F19="","",SUMIFS('Barang Keluar'!$E:$E,'Barang Keluar'!$A:$A,F19)) -> 0 | I19: =IF($A$4+7*(ROW()-8)-WEEKDAY($A$4,2)+1>$B$4,"",$A$4+7*(ROW()-8)-WEEKDAY($A$4,2)+1) -> 46097 | J19: =IF(I19="","",I19+6) -> 46103 | K19: =IF(I19="","",SUMIFS('Barang Keluar'!$E:$E,'Barang Keluar'!$A:$A,">="&I19,'Barang Keluar'!$A:$A,"<="&J19)) -> 0 | M19: =IF($A$4+0>$B$4,"",$A$4+0) -> 46023 | N19: =IF(M19="","",'Master Barang'!A13) -> PRL-012 | O19: =IF(N19="","",'Master Barang'!B13) -> plastik 1/4kg joyoboyo 100 lembar | P19: =IF(OR(M19="",N19=""),"",SUMIFS('Barang Keluar'!$E:$E,'Barang Keluar'!$A:$A,M19,'Barang Keluar'!$C:$C,N19)) -> 0
... A60: =IFERROR('Master Barang'!A55,"") -> 0 | B60: =IFERROR('Master Barang'!B55,"") -> 0 | C60: =IFERROR('Master Barang'!D55,"") -> 0 | D60: =IF(A60="","",SUMIFS('Barang Keluar'!$E:$E,'Barang Keluar'!$C:$C,A60,'Barang Keluar'!$A:$A,">="&$A$4,'Barang Keluar'!$A:$A,"<="&$B$4)) -> 0 | F60: =IF($A$4+ROW()-8>$B$4,"",$A$4+ROW()-8) -> 46075 | G60: =IF(F60="","",SUMIFS('Barang Keluar'!$E:$E,'Barang Keluar'!$A:$A,F60)) -> 0 | I60: =IF($A$4+7*(ROW()-8)-WEEKDAY($A$4,2)+1>$B$4,"",$A$4+7*(ROW()-8)-WEEKDAY($A$4,2)+1) -> 46384 | J60: =IF(I60="","",I60+6) -> 46390 | K60: =IF(I60="","",SUMIFS('Barang Keluar'!$E:$E,'Barang Keluar'!$A:$A,">="&I60,'Barang Keluar'!$A:$A,"<="&J60)) -> 0 | M60: =IF($A$4+0>$B$4,"",$A$4+0) -> 46023 | N60: =IF(M60="","",'Master Barang'!A54) -> 0 | O60: =IF(N60="","",'Master Barang'!B54) -> 0 | P60: =IF(OR(M60="",N60=""),"",SUMIFS('Barang Keluar'!$E:$E,'Barang Keluar'!$A:$A,M60,'Barang Keluar'!$C:$C,N60)) -> 0
A61: =IFERROR('Master Barang'!A56,"") -> 0 | B61: =IFERROR('Master Barang'!B56,"") -> 0 | C61: =IFERROR('Master Barang'!D56,"") -> 0 | D61: =IF(A61="","",SUMIFS('Barang Keluar'!$E:$E,'Barang Keluar'!$C:$C,A61,'Barang Keluar'!$A:$A,">="&$A$4,'Barang Keluar'!$A:$A,"<="&$B$4)) -> 0 | F61: =IF($A$4+ROW()-8>$B$4,"",$A$4+ROW()-8) -> 46076 | G61: =IF(F61="","",SUMIFS('Barang Keluar'!$E:$E,'Barang Keluar'!$A:$A,F61)) -> 0 | M61: =IF($A$4+0>$B$4,"",$A$4+0) -> 46023 | N61: =IF(M61="","",'Master Barang'!A55) -> 0 | O61: =IF(N61="","",'Master Barang'!B55) -> 0 | P61: =IF(OR(M61="",N61=""),"",SUMIFS('Barang Keluar'!$E:$E,'Barang Keluar'!$A:$A,M61,'Barang Keluar'!$C:$C,N61)) -> 0
A62: =IFERROR('Master Barang'!A57,"") -> 0 | B62: =IFERROR('Master Barang'!B57,"") -> 0 | C62: =IFERROR('Master Barang'!D57,"") -> 0 | D62: =IF(A62="","",SUMIFS('Barang Keluar'!$E:$E,'Barang Keluar'!$C:$C,A62,'Barang Keluar'!$A:$A,">="&$A$4,'Barang Keluar'!$A:$A,"<="&$B$4)) -> 0 | F62: =IF($A$4+ROW()-8>$B$4,"",$A$4+ROW()-8) -> 46077 | G62: =IF(F62="","",SUMIFS('Barang Keluar'!$E:$E,'Barang Keluar'!$A:$A,F62)) -> 0 | M62: =IF($A$4+0>$B$4,"",$A$4+0) -> 46023 | N62: =IF(M62="","",'Master Barang'!A56) -> 0 | O62: =IF(N62="","",'Master Barang'!B56) -> 0 | P62: =IF(OR(M62="",N62=""),"",SUMIFS('Barang Keluar'!$E:$E,'Barang Keluar'!$A:$A,M62,'Barang Keluar'!$C:$C,N62)) -> 0
A63: =IFERROR('Master Barang'!A58,"") -> 0 | B63: =IFERROR('Master Barang'!B58,"") -> 0 | C63: =IFERROR('Master Barang'!D58,"") -> 0 | D63: =IF(A63="","",SUMIFS('Barang Keluar'!$E:$E,'Barang Keluar'!$C:$C,A63,'Barang Keluar'!$A:$A,">="&$A$4,'Barang Keluar'!$A:$A,"<="&$B$4)) -> 0 | F63: =IF($A$4+ROW()-8>$B$4,"",$A$4+ROW()-8) -> 46078 | G63: =IF(F63="","",SUMIFS('Barang Keluar'!$E:$E,'Barang Keluar'!$A:$A,F63)) -> 0 | M63: =IF($A$4+0>$B$4,"",$A$4+0) -> 46023 | N63: =IF(M63="","",'Master Barang'!A57) -> 0 | O63: =IF(N63="","",'Master Barang'!B57) -> 0 | P63: =IF(OR(M63="",N63=""),"",SUMIFS('Barang Keluar'!$E:$E,'Barang Keluar'!$A:$A,M63,'Barang Keluar'!$C:$C,N63)) -> 0
A64: =IFERROR('Master Barang'!A59,"") -> 0 | B64: =IFERROR('Master Barang'!B59,"") -> 0 | C64: =IFERROR('Master Barang'!D59,"") -> 0 | D64: =IF(A64="","",SUMIFS('Barang Keluar'!$E:$E,'Barang Keluar'!$C:$C,A64,'Barang Keluar'!$A:$A,">="&$A$4,'Barang Keluar'!$A:$A,"<="&$B$4)) -> 0 | F64: =IF($A$4+ROW()-8>$B$4,"",$A$4+ROW()-8) -> 46079 | G64: =IF(F64="","",SUMIFS('Barang Keluar'!$E:$E,'Barang Keluar'!$A:$A,F64)) -> 0 | M64: =IF($A$4+0>$B$4,"",$A$4+0) -> 46023 | N64: =IF(M64="","",'Master Barang'!A58) -> 0 | O64: =IF(N64="","",'Master Barang'!B58) -> 0 | P64: =IF(OR(M64="",N64=""),"",SUMIFS('Barang Keluar'!$E:$E,'Barang Keluar'!$A:$A,M64,'Barang Keluar'!$C:$C,N64)) -> 0
A65: =IFERROR('Master Barang'!A60,"") -> 0 | B65: =IFERROR('Master Barang'!B60,"") -> 0 | C65: =IFERROR('Master Barang'!D60,"") -> 0 | D65: =IF(A65="","",SUMIFS('Barang Keluar'!$E:$E,'Barang Keluar'!$C:$C,A65,'Barang Keluar'!$A:$A,">="&$A$4,'Barang Keluar'!$A:$A,"<="&$B$4)) -> 0 | F65: =IF($A$4+ROW()-8>$B$4,"",$A$4+ROW()-8) -> 46080 | G65: =IF(F65="","",SUMIFS('Barang Keluar'!$E:$E,'Barang Keluar'!$A:$A,F65)) -> 0 | M65: =IF($A$4+0>$B$4,"",$A$4+0) -> 46023 | N65: =IF(M65="","",'Master Barang'!A59) -> 0 | O65: =IF(N65="","",'Master Barang'!B59) -> 0 | P65: =IF(OR(M65="",N65=""),"",SUMIFS('Barang Keluar'!$E:$E,'Barang Keluar'!$A:$A,M65,'Barang Keluar'!$C:$C,N65)) -> 0
A66: =IFERROR('Master Barang'!A61,"") -> 0 | B66: =IFERROR('Master Barang'!B61,"") -> 0 | C66: =IFERROR('Master Barang'!D61,"") -> 0 | D66: =IF(A66="","",SUMIFS('Barang Keluar'!$E:$E,'Barang Keluar'!$C:$C,A66,'Barang Keluar'!$A:$A,">="&$A$4,'Barang Keluar'!$A:$A,"<="&$B$4)) -> 0 | F66: =IF($A$4+ROW()-8>$B$4,"",$A$4+ROW()-8) -> 46081 | G66: =IF(F66="","",SUMIFS('Barang Keluar'!$E:$E,'Barang Keluar'!$A:$A,F66)) -> 0 | M66: =IF($A$4+0>$B$4,"",$A$4+0) -> 46023 | N66: =IF(M66="","",'Master Barang'!A60) -> 0 | O66: =IF(N66="","",'Master Barang'!B60) -> 0 | P66: =IF(OR(M66="",N66=""),"",SUMIFS('Barang Keluar'!$E:$E,'Barang Keluar'!$A:$A,M66,'Barang Keluar'!$C:$C,N66)) -> 0
A67: =IFERROR('Master Barang'!A62,"") -> 0 | B67: =IFERROR('Master Barang'!B62,"") -> 0 | C67: =IFERROR('Master Barang'!D62,"") -> 0 | D67: =IF(A67="","",SUMIFS('Barang Keluar'!$E:$E,'Barang Keluar'!$C:$C,A67,'Barang Keluar'!$A:$A,">="&$A$4,'Barang Keluar'!$A:$A,"<="&$B$4)) -> 0 | F67: =IF($A$4+ROW()-8>$B$4,"",$A$4+ROW()-8) -> 46082 | G67: =IF(F67="","",SUMIFS('Barang Keluar'!$E:$E,'Barang Keluar'!$A:$A,F67)) -> 0 | M67: =IF($A$4+0>$B$4,"",$A$4+0) -> 46023 | N67: =IF(M67="","",'Master Barang'!A61) -> 0 | O67: =IF(N67="","",'Master Barang'!B61) -> 0 | P67: =IF(OR(M67="",N67=""),"",SUMIFS('Barang Keluar'!$E:$E,'Barang Keluar'!$A:$A,M67,'Barang Keluar'!$C:$C,N67)) -> 0
A68: =IFERROR('Master Barang'!A63,"") -> 0 | B68: =IFERROR('Master Barang'!B63,"") -> 0 | C68: =IFERROR('Master Barang'!D63,"") -> 0 | D68: =IF(A68="","",SUMIFS('Barang Keluar'!$E:$E,'Barang Keluar'!$C:$C,A68,'Barang Keluar'!$A:$A,">="&$A$4,'Barang Keluar'!$A:$A,"<="&$B$4)) -> 0 | F68: =IF($A$4+ROW()-8>$B$4,"",$A$4+ROW()-8) -> 46083 | G68: =IF(F68="","",SUMIFS('Barang Keluar'!$E:$E,'Barang Keluar'!$A:$A,F68)) -> 0 | M68: =IF($A$4+0>$B$4,"",$A$4+0) -> 46023 | N68: =IF(M68="","",'Master Barang'!A62) -> 0 | O68: =IF(N68="","",'Master Barang'!B62) -> 0 | P68: =IF(OR(M68="",N68=""),"",SUMIFS('Barang Keluar'!$E:$E,'Barang Keluar'!$A:$A,M68,'Barang Keluar'!$C:$C,N68)) -> 0
A69: =IFERROR('Master Barang'!A64,"") -> 0 | B69: =IFERROR('Master Barang'!B64,"") -> 0 | C69: =IFERROR('Master Barang'!D64,"") -> 0 | D69: =IF(A69="","",SUMIFS('Barang Keluar'!$E:$E,'Barang Keluar'!$C:$C,A69,'Barang Keluar'!$A:$A,">="&$A$4,'Barang Keluar'!$A:$A,"<="&$B$4)) -> 0 | F69: =IF($A$4+ROW()-8>$B$4,"",$A$4+ROW()-8) -> 46084 | G69: =IF(F69="","",SUMIFS('Barang Keluar'!$E:$E,'Barang Keluar'!$A:$A,F69)) -> 0 | M69: =IF($A$4+0>$B$4,"",$A$4+0) -> 46023 | N69: =IF(M69="","",'Master Barang'!A63) -> 0 | O69: =IF(N69="","",'Master Barang'!B63) -> 0 | P69: =IF(OR(M69="",N69=""),"",SUMIFS('Barang Keluar'!$E:$E,'Barang Keluar'!$A:$A,M69,'Barang Keluar'!$C:$C,N69)) -> 0
A70: =IFERROR('Master Barang'!A65,"") -> 0 | B70: =IFERROR('Master Barang'!B65,"") -> 0 | C70: =IFERROR('Master Barang'!D65,"") -> 0 | D70: =IF(A70="","",SUMIFS('Barang Keluar'!$E:$E,'Barang Keluar'!$C:$C,A70,'Barang Keluar'!$A:$A,">="&$A$4,'Barang Keluar'!$A:$A,"<="&$B$4)) -> 0 | F70: =IF($A$4+ROW()-8>$B$4,"",$A$4+ROW()-8) -> 46085 | G70: =IF(F70="","",SUMIFS('Barang Keluar'!$E:$E,'Barang Keluar'!$A:$A,F70)) -> 0 | M70: =IF($A$4+0>$B$4,"",$A$4+0) -> 46023 | N70: =IF(M70="","",'Master Barang'!A64) -> 0 | O70: =IF(N70="","",'Master Barang'!B64) -> 0 | P70: =IF(OR(M70="",N70=""),"",SUMIFS('Barang Keluar'!$E:$E,'Barang Keluar'!$A:$A,M70,'Barang Keluar'!$C:$C,N70)) -> 0
A71: =IFERROR('Master Barang'!A66,"") -> 0 | B71: =IFERROR('Master Barang'!B66,"") -> 0 | C71: =IFERROR('Master Barang'!D66,"") -> 0 | D71: =IF(A71="","",SUMIFS('Barang Keluar'!$E:$E,'Barang Keluar'!$C:$C,A71,'Barang Keluar'!$A:$A,">="&$A$4,'Barang Keluar'!$A:$A,"<="&$B$4)) -> 0 | F71: =IF($A$4+ROW()-8>$B$4,"",$A$4+ROW()-8) -> 46086 | G71: =IF(F71="","",SUMIFS('Barang Keluar'!$E:$E,'Barang Keluar'!$A:$A,F71)) -> 0 | M71: =IF($A$4+0>$B$4,"",$A$4+0) -> 46023 | N71: =IF(M71="","",'Master Barang'!A65) -> 0 | O71: =IF(N71="","",'Master Barang'!B65) -> 0 | P71: =IF(OR(M71="",N71=""),"",SUMIFS('Barang Keluar'!$E:$E,'Barang Keluar'!$A:$A,M71,'Barang Keluar'!$C:$C,N71)) -> 0
A72: =IFERROR('Master Barang'!A67,"") -> 0 | B72: =IFERROR('Master Barang'!B67,"") -> 0 | C72: =IFERROR('Master Barang'!D67,"") -> 0 | D72: =IF(A72="","",SUMIFS('Barang Keluar'!$E:$E,'Barang Keluar'!$C:$C,A72,'Barang Keluar'!$A:$A,">="&$A$4,'Barang Keluar'!$A:$A,"<="&$B$4)) -> 0 | F72: =IF($A$4+ROW()-8>$B$4,"",$A$4+ROW()-8) -> 46087 | G72: =IF(F72="","",SUMIFS('Barang Keluar'!$E:$E,'Barang Keluar'!$A:$A,F72)) -> 0 | M72: =IF($A$4+0>$B$4,"",$A$4+0) -> 46023 | N72: =IF(M72="","",'Master Barang'!A66) -> 0 | O72: =IF(N72="","",'Master Barang'!B66) -> 0 | P72: =IF(OR(M72="",N72=""),"",SUMIFS('Barang Keluar'!$E:$E,'Barang Keluar'!$A:$A,M72,'Barang Keluar'!$C:$C,N72)) -> 0
... A107: =IFERROR('Master Barang'!A102,"") -> 0 | B107: =IFERROR('Master Barang'!B102,"") -> 0 | C107: =IFERROR('Master Barang'!D102,"") -> 0 | D107: =IF(A107="","",SUMIFS('Barang Keluar'!$E:$E,'Barang Keluar'!$C:$C,A107,'Barang Keluar'!$A:$A,">="&$A$4,'Barang Keluar'!$A:$A,"<="&$B$4)) -> 0 | F107: =IF($A$4+ROW()-8>$B$4,"",$A$4+ROW()-8) -> 46122 | G107: =IF(F107="","",SUMIFS('Barang Keluar'!$E:$E,'Barang Keluar'!$A:$A,F107)) -> 0 | M107: =IF($A$4+0>$B$4,"",$A$4+0) -> 46023 | N107: =IF(M107="","",'Master Barang'!A101) -> 0 | O107: =IF(N107="","",'Master Barang'!B101) -> 0 | P107: =IF(OR(M107="",N107=""),"",SUMIFS('Barang Keluar'!$E:$E,'Barang Keluar'!$A:$A,M107,'Barang Keluar'!$C:$C,N107)) -> 0
A108: =IFERROR('Master Barang'!A103,"") -> 0 | B108: =IFERROR('Master Barang'!B103,"") -> 0 | C108: =IFERROR('Master Barang'!D103,"") -> 0 | D108: =IF(A108="","",SUMIFS('Barang Keluar'!$E:$E,'Barang Keluar'!$C:$C,A108,'Barang Keluar'!$A:$A,">="&$A$4,'Barang Keluar'!$A:$A,"<="&$B$4)) -> 0 | F108: =IF($A$4+ROW()-8>$B$4,"",$A$4+ROW()-8) -> 46123 | G108: =IF(F108="","",SUMIFS('Barang Keluar'!$E:$E,'Barang Keluar'!$A:$A,F108)) -> 0 | M108: =IF($A$4+1>$B$4,"",$A$4+1) -> 46024 | N108: =IF(M108="","",'Master Barang'!A2) -> PRL-001 | O108: =IF(N108="","",'Master Barang'!B2) -> natura desinfectant food grade 5l | P108: =IF(OR(M108="",N108=""),"",SUMIFS('Barang Keluar'!$E:$E,'Barang Keluar'!$A:$A,M108,'Barang Keluar'!$C:$C,N108)) -> 0
A109: =IFERROR('Master Barang'!A104,"") -> 0 | B109: =IFERROR('Master Barang'!B104,"") -> 0 | C109: =IFERROR('Master Barang'!D104,"") -> 0 | D109: =IF(A109="","",SUMIFS('Barang Keluar'!$E:$E,'Barang Keluar'!$C:$C,A109,'Barang Keluar'!$A:$A,">="&$A$4,'Barang Keluar'!$A:$A,"<="&$B$4)) -> 0 | F109: =IF($A$4+ROW()-8>$B$4,"",$A$4+ROW()-8) -> 46124 | G109: =IF(F109="","",SUMIFS('Barang Keluar'!$E:$E,'Barang Keluar'!$A:$A,F109)) -> 0 | M109: =IF($A$4+1>$B$4,"",$A$4+1) -> 46024 | N109: =IF(M109="","",'Master Barang'!A3) -> PRL-002 | O109: =IF(N109="","",'Master Barang'!B3) -> sunlight cairan pencuci piring 5l | P109: =IF(OR(M109="",N109=""),"",SUMIFS('Barang Keluar'!$E:$E,'Barang Keluar'!$A:$A,M109,'Barang Keluar'!$C:$C,N109)) -> 0
A110: =IFERROR('Master Barang'!A105,"") -> 0 | B110: =IFERROR('Master Barang'!B105,"") -> 0 | C110: =IFERROR('Master Barang'!D105,"") -> 0 | D110: =IF(A110="","",SUMIFS('Barang Keluar'!$E:$E,'Barang Keluar'!$C:$C,A110,'Barang Keluar'!$A:$A,">="&$A$4,'Barang Keluar'!$A:$A,"<="&$B$4)) -> 0 | F110: =IF($A$4+ROW()-8>$B$4,"",$A$4+ROW()-8) -> 46125 | G110: =IF(F110="","",SUMIFS('Barang Keluar'!$E:$E,'Barang Keluar'!$A:$A,F110)) -> 0 | M110: =IF($A$4+1>$B$4,"",$A$4+1) -> 46024 | N110: =IF(M110="","",'Master Barang'!A4) -> PRL-003 | O110: =IF(N110="","",'Master Barang'!B4) -> oixs cleaner 1l | P110: =IF(OR(M110="",N110=""),"",SUMIFS('Barang Keluar'!$E:$E,'Barang Keluar'!$A:$A,M110,'Barang Keluar'!$C:$C,N110)) -> 0
A111: =IFERROR('Master Barang'!A106,"") -> 0 | B111: =IFERROR('Master Barang'!B106,"") -> 0 | C111: =IFERROR('Master Barang'!D106,"") -> 0 | D111: =IF(A111="","",SUMIFS('Barang Keluar'!$E:$E,'Barang Keluar'!$C:$C,A111,'Barang Keluar'!$A:$A,">="&$A$4,'Barang Keluar'!$A:$A,"<="&$B$4)) -> 0 | F111: =IF($A$4+ROW()-8>$B$4,"",$A$4+ROW()-8) -> 46126 | G111: =IF(F111="","",SUMIFS('Barang Keluar'!$E:$E,'Barang Keluar'!$A:$A,F111)) -> 0 | M111: =IF($A$4+1>$B$4,"",$A$4+1) -> 46024 | N111: =IF(M111="","",'Master Barang'!A5) -> PRL-004 | O111: =IF(N111="","",'Master Barang'!B5) -> be clean tissue serbaguna | P111: =IF(OR(M111="",N111=""),"",SUMIFS('Barang Keluar'!$E:$E,'Barang Keluar'!$A:$A,M111,'Barang Keluar'!$C:$C,N111)) -> 0
A112: =IFERROR('Master Barang'!A107,"") -> 0 | B112: =IFERROR('Master Barang'!B107,"") -> 0 | C112: =IFERROR('Master Barang'!D107,"") -> 0 | D112: =IF(A112="","",SUMIFS('Barang Keluar'!$E:$E,'Barang Keluar'!$C:$C,A112,'Barang Keluar'!$A:$A,">="&$A$4,'Barang Keluar'!$A:$A,"<="&$B$4)) -> 0 | F112: =IF($A$4+ROW()-8>$B$4,"",$A$4+ROW()-8) -> 46127 | G112: =IF(F112="","",SUMIFS('Barang Keluar'!$E:$E,'Barang Keluar'!$A:$A,F112)) -> 0 | M112: =IF($A$4+1>$B$4,"",$A$4+1) -> 46024 | N112: =IF(M112="","",'Master Barang'!A6) -> PRL-005 | O112: =IF(N112="","",'Master Barang'!B6) -> spons cuci hijau | P112: =IF(OR(M112="",N112=""),"",SUMIFS('Barang Keluar'!$E:$E,'Barang Keluar'!$A:$A,M112,'Barang Keluar'!$C:$C,N112)) -> 0
A113: =IFERROR('Master Barang'!A108,"") -> 0 | B113: =IFERROR('Master Barang'!B108,"") -> 0 | C113: =IFERROR('Master Barang'!D108,"") -> 0 | D113: =IF(A113="","",SUMIFS('Barang Keluar'!$E:$E,'Barang Keluar'!$C:$C,A113,'Barang Keluar'!$A:$A,">="&$A$4,'Barang Keluar'!$A:$A,"<="&$B$4)) -> 0 | F113: =IF($A$4+ROW()-8>$B$4,"",$A$4+ROW()-8) -> 46128 | G113: =IF(F113="","",SUMIFS('Barang Keluar'!$E:$E,'Barang Keluar'!$A:$A,F113)) -> 0 | M113: =IF($A$4+1>$B$4,"",$A$4+1) -> 46024 | N113: =IF(M113="","",'Master Barang'!A7) -> PRL-006 | O113: =IF(N113="","",'Master Barang'!B7) -> sabut cuci stainless | P113: =IF(OR(M113="",N113=""),"",SUMIFS('Barang Keluar'!$E:$E,'Barang Keluar'!$A:$A,M113,'Barang Keluar'!$C:$C,N113)) -> 0
A114: =IFERROR('Master Barang'!A109,"") -> 0 | B114: =IFERROR('Master Barang'!B109,"") -> 0 | C114: =IFERROR('Master Barang'!D109,"") -> 0 | D114: =IF(A114="","",SUMIFS('Barang Keluar'!$E:$E,'Barang Keluar'!$C:$C,A114,'Barang Keluar'!$A:$A,">="&$A$4,'Barang Keluar'!$A:$A,"<="&$B$4)) -> 0 | F114: =IF($A$4+ROW()-8>$B$4,"",$A$4+ROW()-8) -> 46129 | G114: =IF(F114="","",SUMIFS('Barang Keluar'!$E:$E,'Barang Keluar'!$A:$A,F114)) -> 0 | M114: =IF($A$4+1>$B$4,"",$A$4+1) -> 46024 | N114: =IF(M114="","",'Master Barang'!A8) -> PRL-007 | O114: =IF(N114="","",'Master Barang'!B8) -> plastik kresek besar merah 50pc | P114: =IF(OR(M114="",N114=""),"",SUMIFS('Barang Keluar'!$E:$E,'Barang Keluar'!$A:$A,M114,'Barang Keluar'!$C:$C,N114)) -> 0
A115: =IFERROR('Master Barang'!A110,"") -> 0 | B115: =IFERROR('Master Barang'!B110,"") -> 0 | C115: =IFERROR('Master Barang'!D110,"") -> 0 | D115: =IF(A115="","",SUMIFS('Barang Keluar'!$E:$E,'Barang Keluar'!$C:$C,A115,'Barang Keluar'!$A:$A,">="&$A$4,'Barang Keluar'!$A:$A,"<="&$B$4)) -> 0 | F115: =IF($A$4+ROW()-8>$B$4,"",$A$4+ROW()-8) -> 46130 | G115: =IF(F115="","",SUMIFS('Barang Keluar'!$E:$E,'Barang Keluar'!$A:$A,F115)) -> 0 | M115: =IF($A$4+1>$B$4,"",$A$4+1) -> 46024 | N115: =IF(M115="","",'Master Barang'!A9) -> PRL-008 | O115: =IF(N115="","",'Master Barang'!B9) -> lap besar | P115: =IF(OR(M115="",N115=""),"",SUMIFS('Barang Keluar'!$E:$E,'Barang Keluar'!$A:$A,M115,'Barang Keluar'!$C:$C,N115)) -> 0
A116: =IFERROR('Master Barang'!A111,"") -> 0 | B116: =IFERROR('Master Barang'!B111,"") -> 0 | C116: =IFERROR('Master Barang'!D111,"") -> 0 | D116: =IF(A116="","",SUMIFS('Barang Keluar'!$E:$E,'Barang Keluar'!$C:$C,A116,'Barang Keluar'!$A:$A,">="&$A$4,'Barang Keluar'!$A:$A,"<="&$B$4)) -> 0 | F116: =IF($A$4+ROW()-8>$B$4,"",$A$4+ROW()-8) -> 46131 | G116: =IF(F116="","",SUMIFS('Barang Keluar'!$E:$E,'Barang Keluar'!$A:$A,F116)) -> 0 | M116: =IF($A$4+1>$B$4,"",$A$4+1) -> 46024 | N116: =IF(M116="","",'Master Barang'!A10) -> PRL-009 | O116: =IF(N116="","",'Master Barang'!B10) -> lap microfiber | P116: =IF(OR(M116="",N116=""),"",SUMIFS('Barang Keluar'!$E:$E,'Barang Keluar'!$A:$A,M116,'Barang Keluar'!$C:$C,N116)) -> 0
...

Sheet Master Barang
A1: Kode Barang | B1: Nama Barang | C1: Kategori | D1: Satuan | E1: Stok Awal | F1: Stok Minimum | G1: Lokasi/Rak | H1: Keterangan | I1: Column1
A2: PRL-001 | B2: natura desinfectant food grade 5l | C2: peralatan | D2: pcs | E2: 2 | F2: 5 | G2: gudang peralatan | I2: tanggal so gudang per 21 september 2026
A3: PRL-002 | B3: sunlight cairan pencuci piring 5l | C3: peralatan | D3: pcs | E3: 4 | F3: 5 | G3: gudang peralatan
A4: PRL-003 | B4: oixs cleaner 1l | C4: peralatan | D4: pcs | E4: 1 | F4: 5 | G4: gudang peralatan
A5: PRL-004 | B5: be clean tissue serbaguna | C5: peralatan | D5: pcs | E5: 3 | F5: 5 | G5: gudang peralatan
A6: PRL-005 | B6: spons cuci hijau | C6: peralatan | D6: pcs | E6: 37 | F6: 10 | G6: gudang peralatan
A7: PRL-006 | B7: sabut cuci stainless | C7: peralatan | D7: pcs | E7: 22 | F7: 5 | G7: gudang peralatan
A8: PRL-007 | B8: plastik kresek besar merah 50pc | C8: peralatan | D8: pack | E8: 8 | F8: 5 | G8: gudang peralatan
A9: PRL-008 | B9: lap besar | C9: peralatan | D9: pcs | E9: 4 | F9: 5 | G9: gudang peralatan
A10: PRL-009 | B10: lap microfiber | C10: peralatan | D10: pcs | E10: 67 | F10: 5 | G10: gudang peralatan
A11: PRL-010 | B11: lap kecil | C11: peralatan | D11: pcs | E11: 7 | F11: 5 | G11: gudang peralatan
A12: PRL-011 | B12: kanebo kecil | C12: peralatan | D12: pcs | E12: 6 | F12: 5 | G12: gudang peralatan
A13: PRL-012 | B13: plastik 1/4kg joyoboyo 100 lembar | C13: peralatan | D13: pack | E13: 28 | F13: 5 | G13: gudang peralatan
A14: PRL-013 | B14: sarung tangan plastik kaka 100 pcs | C14: peralatan | D14: pack | E14: 21 | F14: 5 | G14: gudang peralatan
... A33: PRL-032 | B33: plastik packaging ag box uk sedang | C33: peralatan | D33: pcs | E33: 2000 | F33: 100 | G33: gudang peralatan
A34: PRL-033

Sheet rekap pengeluaran peraltan
F1: rekap pengeluaran barang peralatan
A3: tanggal | B3: nama | C3: qty | D3: jam ambil | E3: relawan | F3: pic | I3: total penggunaan per periode 1 mingguan | J3: qty
A4: 20 sept 2026 | B4: kresek merah | C4: 1 pack | D4: 19.55 | E4: roni | F4: teguh | I4: natura desinfectant food grade 5l
A5: 20 sept 2026 | B5: trashbag 80x10 | C5: 1 pack | D5: 20.30 | E5: puspitasari | F5: ade | I5: sunlight cairan pencuci piring 5l
A6: 20 sept 2026 | B6: obat mylanta | C6: 1 kaplet | D6: 21.37 | E6: saiful | F6: ade | I6: oixs cleaner 1l
A7: 20 sept 2026 | B7: handsaplast | C7: 2 biji | D7: 23.00 | E7: nafis | F7: ade | I7: be clean tissue serbaguna
A8: 20 sept 2026 | B8: handsaplast | C8: 2 biji | D8: 23.17 | E8: usli | F8: ade | I8: spons cuci hijau
A9: 20 sept 2026 | B9: tissue | C9: 1 pack | D9: 23.17 | E9: b sri | F9: ade | I9: sabut cuci stainless
A10: 21 sept 2026 | B10: sarung tangan | C10: 1 bendel | D10: 23.17 | E10: b sri | F10: ade | I10: plastik kresek besar merah 50pc
A11: 21 sept 2026 | B11: trash bag 80x10 | C11: 1 pack | D11: 01.36 | E11: saiful | F11: ade | I11: lap besar
A12: 21 sept 2026 | B12: masker 1 pack hijab | C12: 1 pack | D12: 03.03 | E12: lutvya | F12: riski | I12: lap microfiber
A13: 21 sept 2026 | B13: plastik buah | C13: 7 pack | D13: 03.03 | E13: lutvya | F13: riski | I13: lap kecil
A14: 21 sept 2026 | B14: sarung tangan | C14: 1 pack | D14: 03.03 | E14: lutvya | F14: riski | I14: kanebo kecil
A15: 21 sept 2026 | B15: trashbag 60x10 | C15: 1 pack | D15: 03.21 | E15: saiful | F15: ade | I15: plastik 1/4kg joyoboyo 100 lembar
... A35: 22 sept 2026 | B35: trash bag 80x10 | C35: 1 pack | D35: 20.00 | E35: saipul | F35: ade | I35: plastik packaging ag box uk sedang
A36: 22 sept 2026 | B36: tissue dapur besar | C36: 1 pack | D36: 19.43 | E36: bu sri | F36: ade
A37: 22 sept 2026 | B37: trashbag 80/100 | C37: 1 pack | D37: 19.43 | E37: bu sri | F37: ade
A38: 23 sept 2026 | B38: hansaplast luka | C38: 2 biji | D38: 03.37 | E38: arip | F38: ade
A39: 23 sept 2026 | B39: sunlight jerigen 5l | C39: 1 jurigen | D39: 05.12 | E39: saipul | F39: ade
A40: 23 sept 2026 | B40: sarung tangan karet biru | C40: 1 pack | D40: 12.05 | E40: atta | F40: akmal
A41: 23 sept 2026 | B41: sunlight jerigen 5l | C41: 1 jurigen | D41: 13.35 | E41: fasa | F41: akmal
A42: 23 sept 2026 | B42: trashbag 80/100 | C42: 1 pack | D42: 19.39 | E42: roni | F42: teguh
A43: 23 sept 2026 | B43: tissue dapur besar | C43: 1 pack | D43: 22.58 | E43: bu sri | F43: ade
A44: 23 sept 2026 | B44: sarung tangan karet biru | C44: 1 pack | D44: 22.58 | E44: bu sri | F44: ade
A45: 23 sept 2026 | B45: trash bag 80x10 | C45: 1 pack | D45: 22.58 | E45: bu sri | F45: ade
A46: 24 sept 2026 | B46: plastik wrap | C46: 1 gulung | D46: 01.00 | E46: anggita | F46: ade
A47: 24 sept 2026 | B47: sarung tangan biru | C47: 1 pack | D47: 08.12 | E47: nabila | F47: teguh
... A63: 24 sept 2026 | B63: trash bag 80x10 | C63: 1 pack | D63: 11.29 | E63: nabila | F63: teguh

Sheet rekap order dan menu
E2: rekap menu, po dan bahan perperiode
E3: periode tanggal 20-24 september 2026
Q5: total pengeluaran bahan permingguan | AA5: sisa bahan gudang
A6: no | B6: total penerima manfaat | C6: menu | D6: tanggal | E6: tanggal po berarti h-1 | F6: kategori | G6: nama barang | H6: qty | I6: datang dan timbang | J6: supplier | K6: jam datang | L6: catatan | M6: pic | O6: no | P6: kategori | Q6: nama barang | R6: 46285 | S6: 46286 | T6: 46287 | U6: 46288 | V6: 46289 | W6: total | X6: satuan
A7: 1 | B7: 3044 | C7: nasi putih | D7: senin, 20 sept 2026 | E7: minggu, 19 sept 2026 | F7: protein | G7: ayam potong | H7: 264 kg | I7: 264kg | J7: ayam segar fajar | K7: 09.00 | M7: akmal | O7: 1 | P7: protein hewani | Q7: ayam potong | R7: 264 | V7: 310 | W7: =SUM(R7:V7) -> 574 | X7: kg
C8: ayam krispi sambal dan selada | G8: tahu putih | H8: 520 pcs | I8: 520pcs | J8: tahu rio | K8: 09.30 | M8: akmal | Q8: telur ayam | S8: 21 | T8: 1 | U8: 21 | W8: =SUM(R8:V8) -> 43 | X8: krat
C9: tahu cabe garam | Q9: ayam fillet dada tanpa kulit | T9: 145 | W9: =SUM(R9:V9) -> 145 | X9: kg
C10: steam buncis wortel | F10: sembako | G10: gula 1 kg | H10: 10pcs | I10: 10kg | P10: lain lain | Q10: lontong | U10: 3060 | W10: =SUM(R10:V10) -> 3060 | X10: pcs
G11: royco | H11: 2 dus | I11: 2dus
C12: b3 | G12: soda kue | H12: 1kg | I12: 1kg | J12: tumpang grosir | K12: 14.53 | M12: akmal | O12: 2 | P12: protein nabati | Q12: tahu kotak | R12: 520 | T12: 527 | U12: 510 | W12: =SUM(R12:V12) -> 1557 | X12: pcs
C13: nasi putih | G13: t segitiga | H13: 3 sak | I13: 3sak | Q13: tempe | U13: 77 | V13: 78 | W13: =SUM(R13:V13) -> 155 | X13: layah
C14: ayam krispi dan orak arik telur | G14: tropical 2l | H14: 9 dus | I14: 9dus | Q14: tahu sutra | S14: 470 | W14: =SUM(R14:V14) -> 470 | X14: pack
C15: tahu kecap | G15: beras mentari 25kg | H15: 7 sak | I15: 7sak
C16: steam buncis wortel | O16: 3 | P16: sembako | Q16: beras mentari 25kg | R16: 7 | S16: 7 | T16: 7 | V16: 7 | W16: =SUM(R16:V16) -> 28 | X16: sak
F17: sayur dan buah | G17: buncis | H17: 65kg | I17: 66kg | Q17: minyak goreng tropical 2l | R17: 9 | T17: 6 | U17: 5 | V17: 5 | W17: =SUM(R17:V17) -> 25 | X17: dus
G18: wortel | H18: 65kg | I18: 66kg | Q18: royco | R18: 2 | U18: 1 | W18: =SUM(R18:V18) -> 3 | X18: dus
G19: tomat buah | H19: 25 kg | I19: 25kg | Q19: tepung segitiga | R19: 3 | W19: =SUM(R19:V19) -> 3 | X19: sak
G20: cabe rawit | H20: 8kg | I20: 8kg | J20: pak beni | K20: 16.19 | M20: akmal | Q20: gula 1kg | R20: 10 | S20: 5 | W20: =SUM(R20:V20) -> 15 | X20: kg
G21: daun jeruk | H21: 1kg | I21: 1kg | Q21: soda kue 1kg | R21: 1 | W21: =SUM(R21:V21) -> 1 | X21: kg
G22: bawang putih | H22: 8kg | I22: 8kg | Q22: terasi | R22: 8 | W22: =SUM(R22:V22) -> 8 | X22: kg
G23: bawang merah | H23: 5kg | I23: 5kg | Q23: mie kuning | S23: 9 | W23: =SUM(R23:V23) -> 9 | X23: pack
G24: daun bawang | H24: 5kg | I24: 5kg | Q24: saos tomat delmonte 1kg | S24: 4 | W24: =SUM(R24:V24) -> 4 | X24: dus
G25: jeruk limau | H25: 1/2kg | I25: 1/2kg | Q25: saos sambal delmonte 1kg | S25: 2 | W25: =SUM(R25:V25) -> 2 | X25: dus
G26: cabe kriting | H26: 5kg | I26: 5kg | Q26: susu plain 115ml | S26: 3060 | W26: =SUM(R26:V26) -> 3060 | X26: pcs
G27: melon | H27: 121pc | I27: 207kg | Q27: tepung panir | T27: 1 | W27: =SUM(R27:V27) -> 1 | X27: sak
G28: tambahan terasi | H28: 8kg | I28: 8kg | Q28: garam | T28: 2 | W28: =SUM(R28:V28) -> 2 | X28: bal
Q29: kulit lumpia merk finna | T29: 250 | W29: =SUM(R29:V29) -> 250 | X29: pcs
Q30: bumbu bmm kari | T30: 2 | W30: =SUM(R30:V30) -> 2 | X30: bal
A31: 2 | B31: 2571 | C31: nasi putih | D31: selasa,21 sept 2026 | E31: senin, 20 sept 2026 | F31: protein | G31: telur ayam | H31: 15krat | I31: 15krat | J31: ayam segar tumpang | K31: 08.30 | M31: akmal | Q31: bumbu sasa kari 40kg | T31: 20 | W31: =SUM(R31:V31) -> 20 | X31: pack
C32: telur dadar isi mie dan bayam bumbu balado | G32: tahu sutra | H32: 470bks | I32: 470bks | K32: 16.58 | M32: akmal | Q32: santan 1l | U32: 1 | W32: =SUM(R32:V32) -> 1 | X32: dus
C33: tahu sutra goreng isis 2 peranak | Q33: petis udang super | U33: 2 | W33: =SUM(R33:V33) -> 2 | X33: kg
C34: pakco bawang putih | F34: sembako | G34: beras mentari 25kg | H34: 7sak | I34: 7sak | Q34: galon cleo | U34: 10 | W34: =SUM(R34:V34) -> 10 | X34: pcs
C35: susu 115 ml frisian flag | G35: mie kuning (15kg) | H35: 9pack | I35: 9pack | J35: tumpang grosir | K35: 15.07 | M35: akmal | Q35: madu botol | W35: =SUM(R35:V35) -> 0
G36: gula 1 kg | H36: 5kg | I36: 5kg
C37: b3 | G37: saos tomat delmonte 1kg (10pcs) | H37: 4dus | I37: 4dus | O37: 4 | P37: sayur | Q37: buncis | R37: 65 | W37: =SUM(R37:V37) -> 65 | X37: kg
C38: nasi putih | G38: saos sambal delmonte 1kg (10pcs) | H38: 2 dus | I38: 2 dus | Q38: wortel | R38: 65 | T38: 50 | U38: 35 | W38: =SUM(R38:V38) -> 150 | X38: kg
C39: telur dadar isi mie dan bayam | Q39: tomat buah | R39: 25 | W39: =SUM(R39:V39) -> 25 | X39: kg
C40: tahu sutra goreng isis 2 peranak | F40: sayur dan buah | Q40: cabe rawit | R40: 8 | W40: =SUM(R40:V40) -> 8 | X40: kg
C41: pakcoy bawang putih | G41: pakcoy | H41: 220kg | I41: 230kg | Q41: daun jeruk | R41: 1 | W41: =SUM(R41:V41) -> 1 | X41: kg
C42: susu 115 ml frisian flag | G42: bayam | H42: 30kg | I42: 33kg | J42: mas widi | K42: 16.32 | M42: akmal | Q42: bawang putih | R42: 8 | S42: 2 | T42: 5 | W42: =SUM(R42:V42) -> 15 | X42: kg
...

Sheet rekap limbah tercatat
F1: rekap limbah sppg jeru tumpang
F2: periode 18-25 september 2026
A6: hari | B6: tanggal | C6: jenis limbah | D6: jumlah | E6: satuan
A7: jumat | B7: 46283 | C7: karbohidrat | D7: 64.16 | E7: kg
C8: sayur | D8: 48.12 | E8: kg
C9: protein hewani | D9: 16.4 | E9: kg
C10: protein nabati | D10: 24.6 | E10: kg
C11: buah | D11: 8.02 | E11: kg
A13: total | D13: =SUM(D7:D11) -> 161.3 | E13: kg | G13: hitung rumus
A14: senin | B14: 46286 | C14: karbohidrat | D14: 62.92 | E14: kg | G14: karbohidrat | I14: =I19*0.4 -> 0
C15: sayur | D15: 47.19 | E15: kg | G15: sayur | I15: =I19*0.3 -> 0
C16: protein hewani | D16: 15.73 | E16: kg | G16: protein hewani | I16: =I19*0.1 -> 0
C17: protein nabati | D17: 23.6 | E17: kg | G17: protein nabati | I17: =I19*0.15 -> 0
C18: buah | D18: 7.86 | E18: kg | G18: buah | I18: =I19*0.05 -> 0
G19: total
A20: total | D20: =SUM(D14:D19) -> 157.3 | E20: kg
A21: selasa | B21: 46287 | C21: karbohidrat | D21: 59.48 | E21: kg
C22: sayur | D22: 44.61 | E22: kg
C23: protein hewani | D23: 14.87 | E23: kg
C24: protein nabati | D24: 29.74 | E24: kg
C25: buah | D25: 0 | E25: kg
A27: total | D27: =SUM(D21:D26) -> 148.7 | E27: kg
A28: rabu | B28: 46288 | C28: karbohidrat | D28: 69.36 | E28: kg
C29: sayur | D29: 52.02 | E29: kg | G29: total hitung limbah
C30: protein hewani | D30: 17.34 | E30: kg | G30: no | H30: limbah | I30: 46283 | J30: 46286 | K30: 46287 | L30: 46288 | M30: 46289 | N30: total | O30: satuan
C31: protein nabati | D31: 26.01 | E31: kg | G31: 1 | H31: karbohidrat | I31: 64.16 | J31: 62.92 | K31: 59.48 | L31: 69.36 | M31: 55.72 | N31: =SUM(I31:M31) -> 311.64 | O31: kg
C32: buah | D32: 8.67 | E32: kg | G32: 2 | H32: sayur | I32: 48.12 | J32: 47.19 | K32: 44.61 | L32: 52.02 | M32: 41.79 | N32: =SUM(I32:M32) -> 233.73 | O32: kg
G33: 3 | H33: protein hewani | I33: 16.4 | J33: 15.73 | K33: 14.87 | L33: 17.34 | M33: 13.93 | N33: =SUM(I33:M33) -> 78.27 | O33: kg
A34: total | D34: =SUM(D28:D33) -> 173.4 | E34: kg | G34: 4 | H34: protein nabati | I34: 24.6 | J34: 23.6 | K34: 29.74 | L34: 26.01 | M34: 20.89 | N34: =SUM(I34:M34) -> 124.84 | O34: kg
A35: kamis | B35: 46289 | C35: karbohidrat | D35: 55.72 | E35: kg | G35: 5 | H35: buah | I35: 8.02 | J35: 7.86 | K35: 0 | L35: 8.67 | M35: 6.96 | N35: =SUM(I35:M35) -> 31.51 | O35: kg
C36: sayur | D36: 41.79 | E36: kg | L36: total keseluruhan limbah : | N36: =SUM(N31:N35) -> 779.99 | O36: kg
C37: protein hewani | D37: 13.93 | E37: kg
C38: protein nabati | D38: 20.89 | E38: kg
C39: buah | D39: 6.96 | E39: kg
A41: total | D41: =SUM(D35:D40) -> 139.29 | E41: kg
A42: jumat | B42: 46290 | C42: karbohidrat | E42: kg
C43: sayur | E43: kg
C44: protein hewani | E44: kg
C45: protein nabati | E45: kg
C46: buah | E46: kg
...

Sheet rekap stock peralatan datang
D1: stok bahan peralatan datang sppg jeru tumpang
A2: nama | B2: qty | C2: tanggal datang | D2: keterangan / catatan | E2: pembelian | F2: * stok gudang dan belum dibayar jika ada
A3: trashbag 80x100 | B3: 5pack | C3: 46286 | E3: shopee
A4: trashbag 60x100 | B4: 15pack | C4: 46286 | E4: shopee
A5: altamed nurse cap 100pcs | B5: 5 pack | C5: 46287 | E5: shopee
A6: blue sarung tangan karet large 100pcs | B6: 17 pack | C6: 46287 | E6: shopee
A7: sunlight jurigen 5l | B7: 1dus | C7: 46289 | D7: ambil dari stok yang sudah ada dulu 1 dus + 1pc | E7: shopee
A8: tissue dapur kecil tidak ada merk | B8: 50pcs | C8: 46289 | E8: shopee
A9: superpel jurigen 5l | B9: 4pcs | C9: 46292 | E9: shopee
A10: vixal 1l | B10: 2pcs | C10: 46292 | E10: shopee
A11: sunlight jurigen 5l | B11: 9 dus | C11: 46292 | E11: shopee
A12: thinwall 200 ml | B12: 8 pack | C12: 46292 | E12: shopee | F12: tali rafia 1 ball
